Workbook

Sheet 說明
A1: 世界島社區財報整理
A3: 資料期間 | B3: 2021-01 ~ 2026-04 (63 個月)
A4: 帳戶數 | B4: 8 個（跨期合併）
A5: 分類規則來源 | B5: build_world_island_html.py 內 JS regex
A6: 分類大類 | B6: 收入 8 類、支出 12 類
A8: Sheet 1 月度摘要 | B8: 每月收入/支出/結餘總額、帳戶期末總餘額、專款餘額
A9: Sheet 2 收入分類矩陣 | B9: rows=月份, cols=收入分類, values=金額（pivot 表）
A10: Sheet 3 支出分類矩陣 | B10: rows=月份, cols=支出分類, values=金額
A11: Sheet 4 收入明細 | B11: 每筆收入逐項列出，最後一欄為分類結果；其他收入用黃色高亮
A12: Sheet 5 支出明細 | B12: 每筆支出逐項列出，columns: 月份/顯示名稱/金額/分類/Section/議案類別 — 議案類別 column 黃=外牆修繕、藍=納管、橙=電梯
A13: Sheet 6 議案-外牆修繕 | B13: PPT 第 4 頁 data source — SUMIFS 自動從支出明細抓合計
A14: Sheet 7 議案-納管 | B14: 同上，SUMIFS 條件為「納管」
A15: Sheet 8 議案-電梯 | B15: 同上，SUMIFS 條件為「電梯」(崇友月保養 + 各種修繕/零件，排除撥補)
... A24: 議案驗證 | B24: Sheet 6/7 的「合計金額」(B5 SUMIFS 公式) 應 = 「明細加總」(底部 SUM 公式)，差額應為 0
A26: ⚠️ 私人資料 — 僅可於 Google Drive 私人路徑保存，不可進入 git repo 或 public demo

Sheet 月度摘要
A1: 月份 | B1: 收入合計 | C1: 支出合計 | D1: 結餘 | E1: 結餘率 | F1: 帳戶期末總餘額 | G1: 充電樁專款餘額 | H1: 電梯專款餘額 | I1: 暫收款活動筆數 | J1: 收入項目數 | K1: 支出項目數
A2: 2021-01 | B2: 2179294 | C2: 1224893 | D2: 954401 | E2: 0.43794045 | F2: 19202835 | G2: 0 | H2: 0 | I2: 0 | J2: 11 | K2: 30
A3: 2021-02 | B3: 889634 | C3: 1583724 | D3: -694090 | E3: -0.78019725 | F3: 17372468 | G3: 0 | H3: 0 | I3: 8 | J3: 12 | K3: 29
A4: 2021-03 | B4: 98149 | C4: 1277874 | D4: -1179725 | E4: -12.019735 | F4: 16266550 | G4: 0 | H4: 0 | I4: 0 | J4: 12 | K4: 34
A5: 2021-04 | B5: 2315258 | C5: 984380 | D5: 1330878 | E5: 0.57482924 | F5: 17671352 | G5: 0 | H5: 0 | I5: 0 | J5: 10 | K5: 24
A6: 2021-05 | B6: 507549 | C6: 1124613 | D6: -617064 | E6: -1.2157723 | F6: 17148173 | G6: 0 | H6: 0 | I6: 0 | J6: 10 | K6: 30
A7: 2021-06 | B7: 121511 | C7: 1289875 | D7: -1168364 | E7: -9.6152941 | F7: 15954141 | G7: 0 | H7: 0 | I7: 0 | J7: 11 | K7: 31
A8: 2021-07 | B8: 2650284 | C8: 1324208 | D8: 1326076 | E8: 0.50035242 | F8: 17334102 | G8: 0 | H8: 0 | I8: 0 | J8: 14 | K8: 28
A9: 2021-08 | B9: 507211 | C9: 985197 | D9: -477986 | E9: -0.94238098 | F9: 16954040 | G9: 0 | H9: 0 | I9: 0 | J9: 10 | K9: 28
A10: 2021-09 | B10: 80847 | C10: 1673787 | D10: -1592940 | E10: -19.703143 | F10: 15455024 | G10: 0 | H10: 0 | I10: 0 | J10: 10 | K10: 26
A11: 2021-10 | B11: 2373545 | C11: 1119183 | D11: 1254362 | E11: 0.52847618 | F11: 16743271 | G11: 0 | H11: 0 | I11: 0 | J11: 11 | K11: 28
A12: 2021-11 | B12: 618604 | C12: 1619709 | D12: -1001105 | E12: -1.6183293 | F12: 15716090 | G12: 0 | H12: 0 | I12: 0 | J12: 10 | K12: 30
A13: 2021-12 | B13: 199141 | C13: 1114396 | D13: -915255 | E13: -4.5960149 | F13: 14855149 | G13: 0 | H13: 0 | I13: 0 | J13: 10 | K13: 26
... A65: 2026-04 | B65: 5499534 | C65: 2703526 | D65: 2796008 | E65: 0.50840817 | F65: 11623750 | G65: 1865135 | H65: 0 | I65: 4 | J65: 11 | K65: 38
A66: 全期合計 | B66: 90252406 | C66: 91292894 | D66: -1040488 | E66: -0.011528646

Sheet 支出分類矩陣
A1: 月份 | B1: 管理服務費 | C1: 保全服務費 | D1: 清潔服務費 | E1: 電梯保養與修繕 | F1: 機電/消防/弱電/AED | G1: 公共水電瓦斯 | H1: 電話/網路費 | I1: 垃圾廢棄物/園藝 | J1: 工程維修/購置 | K1: 行政/會議/律師 | L1: 內部轉帳 | M1: 其他支出 | N1: 合計
A2: 2021-01 | D2: 199550 | E2: 101050 | F2: 48950 | G2: 87413 | H2: 4978 | I2: 95705 | K2: 46000 | L2: 134077 | M2: 507170 | N2: 1224893
A3: 2021-02 | D3: 209900 | E3: 100000 | F3: 741328 | I3: 52990 | K3: 8000 | L3: 4541 | M3: 374920 | N3: 1491679
A4: 2021-03 | D4: 198000 | E4: 149770 | F4: 95276 | G4: 101777 | H4: 10400 | I4: 52990 | J4: 52650 | K4: 36512 | L4: 66434 | M4: 514065 | N4: 1277874
A5: 2021-04 | D5: 200730 | E5: 100000 | F5: 54132 | G5: 89691 | H5: 5221 | I5: 93700 | L5: 63606 | M5: 377300 | N5: 984380
A6: 2021-05 | D6: 199220 | E6: 146305 | F6: 70160 | G6: 84824 | H6: 4858 | I6: 58000 | J6: 83100 | L6: 71296 | M6: 406850 | N6: 1124613
A7: 2021-06 | D7: 210880 | E7: 195500 | F7: 117350 | G7: 92524 | H7: 5275 | I7: 175280 | J7: 49500 | L7: 75466 | M7: 368100 | N7: 1289875
A8: 2021-07 | D8: 202990 | E8: 115750 | F8: 346855 | G8: 89266 | H8: 4897 | I8: 66500 | K8: 25000 | L8: 66615 | M8: 406335 | N8: 1324208
A9: 2021-08 | D9: 201280 | E9: 104620 | F9: 62550 | G9: 103421 | H9: 5130 | I9: 73700 | L9: 63596 | M9: 370900 | N9: 985197
A10: 2021-09 | D10: 201570 | E10: 105800 | F10: 97750 | G10: 80066 | H10: 5314 | I10: 64840 | J10: 685000 | L10: 63877 | M10: 369570 | N10: 1673787
A11: 2021-10 | D11: 206663 | E11: 100000 | F11: 143490 | G11: 105471 | H11: 5161 | I11: 58000 | J11: 31500 | L11: 64588 | M11: 404310 | N11: 1119183
A12: 2021-11 | D12: 200678 | E12: 117000 | F12: 595100 | G12: 104138 | H12: 5226 | I12: 79780 | J12: 4934 | L12: 63453 | M12: 449400 | N12: 1619709
A13: 2021-12 | D13: 202208 | E13: 123560 | F13: 165668 | G13: 79194 | H13: 4870 | I13: 58000 | J13: 35800 | L13: 65696 | M13: 379400 | N13: 1114396
A14: 2022-01 | D14: 203069 | E14: 100000 | F14: 256220 | G14: 82554 | H14: 5037 | I14: 81200 | J14: 102010 | L14: 63356 | M14: 387400 | N14: 1280846
A15: 2022-02 | D15: 207374 | E15: 134800 | F15: 99010 | G15: 99540 | I15: 67300 | J15: 31500 | L15: 73714 | M15: 384900 | N15: 1098138
A16: 2022-03 | D16: 201945 | E16: 100000 | F16: 113300 | G16: 97724 | H16: 9748 | I16: 81265 | J16: 22500 | K16: 52000 | L16: 74889 | M16: 479400 | N16: 1232771
A17: 2022-04 | D17: 203174 | E17: 136560 | F17: 165750 | G17: 90017 | H17: 5118 | I17: 62400 | L17: 62822 | M17: 398907 | N17: 1124748
A18: 2022-05 | D18: 201000 | E18: 142000 | F18: 91070 | G18: 89633 | H18: 5008 | I18: 84075 | J18: 27150 | L18: 61970 | M18: 379400 | N18: 1081306
A19: 2022-06 | D19: 203930 | E19: 100000 | F19: 48950 | G19: 92053 | H19: 4864 | I19: 67800 | J19: 22800 | L19: 69484 | M19: 396533 | N19: 1006414
A20: 2022-07 | D20: 201000 | E20: 100000 | F20: 48950 | G20: 101869 | H20: 4903 | I20: 66600 | J20: 101950 | L20: 70395 | M20: 383900 | N20: 1079567
A21: 2022-08 | D21: 204885 | E21: 111235 | F21: 48950 | G21: 113741 | H21: 4851 | I21: 86625 | J21: 29900 | K21: 25000 | L21: 60740 | M21: 385827 | N21: 1071754
A22: 2022-09 | D22: 201000 | E22: 130765 | F22: 48950 | G22: 114022 | H22: 5149 | I22: 64800 | J22: 22660 | L22: 69202 | M22: 390900 | N22: 1047448
A23: 2022-10 | D23: 201000 | E23: 115015 | F23: 96950 | G23: 154637 | H23: 4927 | I23: 220400 | J23: 107272 | L23: 69917 | M23: 472650 | N23: 1442768
A24: 2022-11 | D24: 204266 | E24: 200525 | F24: 54515 | G24: 107881 | H24: 4905 | I24: 68400 | J24: 44857 | L24: 61941 | M24: 389550 | N24: 1136840
A25: 2022-12 | D25: 220678 | E25: 114000 | F25: 48950 | G25: 118877 | H25: 5127 | I25: 37700 | J25: 27250 | L25: 74049 | M25: 389550 | N25: 1036181
A26: 2023-01 | D26: 218000 | E26: 306600 | F26: 48950 | G26: 90116 | I26: 95730 | J26: 84000 | L26: 68710 | M26: 389550 | N26: 1301656
A27: 2023-02 | D27: 220174 | E27: 115225 | F27: 583470 | G27: 95142 | H27: 4696 | I27: 100000 | J27: 41460 | L27: 62149 | M27: 444350 | N27: 1666666
A28: 2023-03 | D28: 218000 | E28: 108700 | F28: 48950 | G28: 90833 | H28: 8996 | I28: 79215 | J28: 84350 | K28: 47800 | L28: 67769 | M28: 437550 | N28: 1192163
A29: 2023-04 | D29: 218000 | E29: 128675 | F29: 52940 | G29: 87373 | H29: 4948 | I29: 127850 | J29: 22476 | L29: 66523 | M29: 389550 | N29: 1098335
A30: 2023-05 | D30: 218000 | E30: 222560 | F30: 48950 | G30: 93029 | H30: 4558 | I30: 68800 | J30: 23595 | L30: 60580 | M30: 391820 | N30: 1131892
A31: 2023-06 | D31: 221686 | E31: 106200 | F31: 132360 | G31: 90340 | H31: 4365 | I31: 70000 | J31: 5250 | L31: 72178 | M31: 414350 | N31: 1116729
A32: 2023-07 | D32: 218998 | E32: 120400 | F32: 48950 | G32: 93568 | H32: 4417 | I32: 105985 | J32: 90240 | L32: 63598 | M32: 406989 | N32: 1153145
A33: 2023-08 | D33: 218000 | E33: 104200 | F33: 48950 | G33: 121277 | H33: 4370 | I33: 67000 | J33: 86650 | K33: 25000 | L33: 67806 | M33: 533010 | N33: 1276263
A34: 2023-09 | D34: 220216 | E34: 136900 | F34: 56950 | G34: 105889 | H34: 4472 | I34: 76875 | J34: 14600 | L34: 61962 | M34: 389550 | N34: 1067414
A35: 2023-10 | D35: 218000 | E35: 100000 | F35: 98840 | G35: 127753 | H35: 4314 | I35: 70200 | J35: 43600 | L35: 64522 | M35: 433450 | N35: 1160679
A36: 2023-11 | D36: 222432 | E36: 138675 | F36: 48950 | G36: 97513 | H36: 4631 | I36: 37200 | J36: 114200 | L36: 67185 | M36: 397550 | N36: 1128336
A37: 2023-12 | D37: 228000 | E37: 124600 | F37: 48950 | G37: 92454 | H37: 4474 | I37: 133485 | J37: 239100 | L37: 155538 | M37: 443650 | N37: 1470251
A38: 2024-01 | D38: 230174 | E38: 104200 | F38: 122450 | G38: 100087 | H38: 4604 | I38: 62400 | J38: 73500 | L38: 69974 | M38: 413350 | N38: 1180739
A39: 2024-02 | D39: 228000 | E39: 134175 | F39: 72260 | G39: 115564 | I39: 91150 | J39: 55000 | L39: 62623 | M39: 393550 | N39: 1152322
A40: 2024-03 | D40: 229260 | E40: 109600 | F40: 203140 | G40: 107119 | H40: 8955 | I40: 43000 | J40: 95945 | K40: 51600 | L40: 69175 | M40: 393550 | N40: 1311344
...

Sheet 收入明細
A1: 月份 | B1: 主類 | C1: 子類 | D1: 顯示名稱 | E1: 金額 | F1: 分類
A2: 2021-01 | B2: 元大定存利息 | D2: 元大定存利息 | E2: 416 | F2: 利息收入
A3: 2021-01 | B3: 元大定存利息 | D3: (未命名) | E3: 314 | F3: 其他收入
A4: 2021-01 | B4: 元大定存利息 | D4: (未命名) | E4: 416 | F4: 其他收入
A5: 2021-01 | B5: 元大定存利息 | D5: (未命名) | E5: 654 | F5: 其他收入
A6: 2021-01 | B6: 元大定存利息 | D6: (未命名) | E6: 1308 | F6: 其他收入
A7: 2021-01 | B7: 管理費收入 | D7: 管理費收入 | E7: 5919 | F7: 管理費收入
A8: 2021-01 | B8: 管理費收入 | D8: (未命名) | E8: 13746 | F8: 其他收入
A9: 2021-01 | B9: 管理費收入 | D9: (未命名) | E9: 2145711 | F9: 其他收入
A10: 2021-01 | B10: 裝潢保證金 | D10: 裝潢保證金 | E10: 0 | F10: 暫收款進
A11: 2021-01 | B11: 公設收入 | D11: 公設收入 | E11: 8810 | F11: 公設收入
A12: 2021-01 | B12: 管委會出席費回存 | D12: 管委會出席費回存 | E12: 2000 | F12: 出席費回存
A13: 2021-02 | B13: 元大活期利息 | D13: 元大活期利息 | E13: 0 | F13: 利息收入
A14: 2021-02 | B14: 元大定存利息 | C14: 683000006773 | D14: 元大定存利息 683000006773 | E14: 416 | F14: 利息收入
A15: 2021-02 | B15: 元大定存利息 | C15: 683000014551 | D15: 元大定存利息 683000014551 | E15: 314 | F15: 利息收入
A16: 2021-02 | B16: 元大定存利息 | C16: 683000006745 | D16: 元大定存利息 683000006745 | E16: 416 | F16: 利息收入
A17: 2021-02 | B17: 元大定存利息 | C17: 683000013365 | D17: 元大定存利息 683000013365 | E17: 654 | F17: 利息收入
A18: 2021-02 | B18: 元大定存利息 | C18: 683000016001 | D18: 元大定存利息 683000016001 | E18: 0 | F18: 利息收入
A19: 2021-02 | B19: 管理費收入 | C19: 109第三季 | D19: 管理費收入 109第三季 | E19: 4350 | F19: 管理費收入
A20: 2021-02 | B20: 管理費收入 | C20: 109第四季 | D20: 管理費收入 109第四季 | E20: 4350 | F20: 管理費收入
A21: 2021-02 | B21: 管理費收入 | C21: 110第一季 | D21: 管理費收入 110第一季 | E21: 862002 | F21: 管理費收入
A22: 2021-02 | B22: 管理費收入 | C22: 110第二季 | D22: 管理費收入 110第二季 | E22: 7812 | F22: 管理費收入
A23: 2021-02 | B23: 公設收入 | D23: 公設收入 | E23: 6320 | F23: 公設收入
A24: 2021-02 | B24: 管委會出席費回存 | D24: 管委會出席費回存 | E24: 3000 | F24: 出席費回存
A25: 2021-03 | B25: 元大活期利息 | D25: 元大活期利息 | E25: 0 | F25: 利息收入
A26: 2021-03 | B26: 元大定存利息 | C26: 683000006773 | D26: 元大定存利息 683000006773 | E26: 376 | F26: 利息收入
A27: 2021-03 | B27: 元大定存利息 | C27: 683000014551 | D27: 元大定存利息 683000014551 | E27: 284 | F27: 利息收入
A28: 2021-03 | B28: 元大定存利息 | C28: 683000006745 | D28: 元大定存利息 683000006745 | E28: 376 | F28: 利息收入
A29: 2021-03 | B29: 元大定存利息 | C29: 683000013365 | D29: 元大定存利息 683000013365 | E29: 591 | F29: 利息收入
A30: 2021-03 | B30: 元大定存利息 | C30: 683000016001 | D30: 元大定存利息 683000016001 | E30: 1308 | F30: 利息收入
A31: 2021-03 | B31: 元大定存利息 | C31: 683000016001 | D31: 元大定存利息 683000016001 | E31: 1181 | F31: 利息收入
A32: 2021-03 | B32: 管理費收入 | C32: 110年度Q1 | D32: 管理費收入 110年度Q1 | E32: 28632 | F32: 管理費收入
A33: 2021-03 | B33: 管理費收入 | C33: 110年度Q2 | D33: 管理費收入 110年度Q2 | E33: 40056 | F33: 管理費收入
A34: 2021-03 | B34: 公設收入 | D34: 公設收入 | E34: 11345 | F34: 公設收入
A35: 2021-03 | B35: 管委會出席費回存 | D35: 管委會出席費回存 | E35: 4000 | F35: 出席費回存
A36: 2021-03 | B36: 金創舊衣回收回饋金 | D36: 金創舊衣回收回饋金 | E36: 10000 | F36: 其他收入
A37: 2021-04 | B37: 元大活期利息 | D37: 元大活期利息 | E37: 0 | F37: 利息收入
A38: 2021-04 | B38: 元大定存利息 | C38: 683000006773 | D38: 元大定存利息 683000006773 | E38: 416 | F38: 利息收入
A39: 2021-04 | B39: 元大定存利息 | C39: 683000014551 | D39: 元大定存利息 683000014551 | E39: 314 | F39: 利息收入
A40: 2021-04 | B40: 元大定存利息 | C40: 683000006745 | D40: 元大定存利息 683000006745 | E40: 416 | F40: 利息收入
...

Sheet 支出明細
A1: 月份 | B1: 顯示名稱 | C1: 金額 | D1: 分類 | E1: Section | F1: 議案類別
A2: 小計：固定 661 項、非固定 1202 項、暫收款 0 項
A3: 小計：外牆修繕 14 項、納管 9 項、電梯 139 項、游泳池 39 項 — 給 PPT 第 4 頁 + 「議案-*」 sheet 用
A4: 2021-01 | B4: 零用金撥補(109/12) | C4: 4077 | D4: 零用金/出席費 | E4: 非固定
A5: 2021-01 | B5: 管會會出席費(110/01) | C5: 8000 | D5: 零用金/出席費 | E5: 非固定
A6: 2021-01 | B6: 電梯專用款撥補(110/01) | C6: 50000 | D6: 電梯專款撥款 | E6: 非固定 | F6: 電梯
A7: 2021-01 | B7: 德懋物業管理服務費(109/12) | C7: 359100 | D7: 管服費 | E7: 固定
A8: 2021-01 | B8: 順達清潔服務費(109/12) | C8: 99000 | D8: 清潔費 | E8: 固定
A9: 2021-01 | B9: 義明清潔服務費(109/12) | C9: 99000 | D9: 清潔費 | E9: 固定
A10: 2021-01 | B10: 侑昇-泳池機房保養(109/12) | C10: 3000 | D10: 泳池保養 | E10: 固定 | F10: 游泳池
A11: 2021-01 | B11: 崇友電梯(109/12)電梯保養 | C11: 100000 | D11: 電梯保養 | E11: 固定 | F11: 電梯
A12: 2021-01 | B12: AED(110/01)租賃費 | C12: 1500 | D12: AED | E12: 固定
A13: 2021-01 | B13: 御品寬頻(109/12)網路服務租賃 | C13: 9450 | D13: 電話/網路費 | E13: 固定
A14: 2021-01 | B14: 新鑫堯109/12清潔費(垃圾.資源回收) | C14: 24990 | D14: 清潔費 | E14: 固定
A15: 2021-01 | B15: 太古意門禁維護檢點費(109/12) | C15: 10000 | D15: 弱電/門禁 | E15: 固定
A16: 2021-01 | B16: 鑫禾機電保養費(109/12) | C16: 28000 | D16: 機電保養 | E16: 固定
A17: 2021-01 | B17: 景輝-園藝定期保養(12月) | C17: 28000 | D17: 園藝 | E17: 固定
A18: 2021-01 | B18: 鋐隆清潔用品 | C18: 1550 | D18: 其他 | E18: 非固定
A19: 2021-01 | B19: 英特康-磁扣100個 | C19: 4500 | D19: 其他 | E19: 非固定
A20: 2021-01 | B20: 崇友電梯維修-丙棟電梯紅外線光幕傳輸線 | C20: 1050 | D20: 電梯保養 | E20: 非固定 | F20: 電梯
A21: 2021-01 | B21: 10P乾粉滅火器性能檢查，數量323個 單價$120元，總計$120*323=$38,760元 | C21: 38760 | D21: 其他 | E21: 非固定
A22: 2021-01 | B22: 鑫禾 1.外圍人行道-噴灌重新配管(單價$1,000元) 2.丁棟景觀燈盤-漏電斷路器(單價$1,200元) 3.景觀池-1HP揚水馬達(單價$9,500元) 4.丙棟下水池-A泵主閘閥更換(單價$12,000元) 5.地下室、公廁-LED-MR16 (單價$395元*19盞=$7,505元) 5%稅金$1,560元，總計$1,000+1,200+9,500+12,000+7,505+1,560 =$32,765元 | C22: 32765 | D22: 其他 | E22: 非固定
A23: 2021-01 | B23: 禾順環保-高壓水刀清洗管路 單價$84,000元 | C23: 84000 | D23: 其他 | E23: 非固定
A24: 2021-01 | B24: 請求郁緁企業有限公司損害賠償民事訴訟第一審訴訟代理律師費(費用$45,000元，裁判費$1,000元，總計$46,000元) | C24: 46000 | D24: 其他 | E24: 非固定
A25: 2021-01 | B25: 水質檢測費-大腸桿菌群 | C25: 1200 | D25: 其他 | E25: 非固定
A26: 2021-01 | B26: 慶餘輸出-樓層貼紙 | C26: 8610 | D26: 其他 | E26: 非固定
A27: 2021-01 | B27: 中國石油-柴油 | C27: 9950 | D27: 其他 | E27: 非固定
A28: 2021-01 | B28: 退裝潢保證金 | C28: 80000 | D28: 退裝潢保證金 | E28: 非固定
A29: 2021-01 | B29: 社區電話費(109/12/01-109/12/31)(5630533) | C29: 880 | D29: 電話/網路費 | E29: 非固定
A30: 2021-01 | B30: 社區網路費(109/12/01-109/12/31)(Y123617) | C30: 2199 | D30: 電話/網路費 | E30: 非固定
A31: 2021-01 | B31: 社區網路費(109/12/01-109/12/31)(Y174790) | C31: 1899 | D31: 電話/網路費 | E31: 非固定
A32: 2021-01 | B32: 109年12月公共電費 | C32: 87413 | D32: 公共水電瓦斯 | E32: 非固定
... A38: 2021-02 | B38: 義明清潔服務費(110/02) | C38: 99000 | D38: 清潔費 | E38: 固定
A39: 2021-02 | B39: 侑昇-泳池機房保養(110/02) | C39: 3000 | D39: 泳池保養 | E39: 固定 | F39: 游泳池
A40: 2021-02 | B40: 崇友電梯(110/02)電梯保養 | C40: 100000 | D40: 電梯保養 | E40: 固定 | F40: 電梯
A41: 2021-02 | B41: AED(110/03)租賃費 | C41: 1500 | D41: AED | E41: 固定
A42: 2021-02 | B42: 御品寬頻(110/02)網路服務租賃 | C42: 9450 | D42: 電話/網路費 | E42: 固定
A43: 2021-02 | B43: 新鑫堯110/02清潔費(垃圾.資源回收) | C43: 24990 | D43: 清潔費 | E43: 固定
A44: 2021-02 | B44: 太古意門禁維護檢點費(110/02) | C44: 10000 | D44: 弱電/門禁 | E44: 非固定
A45: 2021-02 | B45: 鑫禾機電保養費(110/02) | C45: 28000 | D45: 機電保養 | E45: 固定
...

Sheet 收入分類矩陣
A1: 月份 | B1: 管理費收入 | C1: 利息收入 | D1: 公設收入 | E1: 出席費回存 | F1: 贊助/活動 | G1: 暫收款進 | H1: 內部轉帳 | I1: 其他收入 | J1: 合計
A2: 2021-01 | B2: 5919 | C2: 416 | D2: 8810 | E2: 2000 | I2: 2162149 | J2: 2179294
A3: 2021-02 | B3: 878514 | C3: 1800 | D3: 6320 | E3: 3000 | J3: 889634
A4: 2021-03 | B4: 68688 | C4: 4116 | D4: 11345 | E4: 4000 | I4: 10000 | J4: 98149
A5: 2021-04 | B5: 2301010 | C5: 3108 | D5: 8140 | E5: 3000 | J5: 2315258
A6: 2021-05 | B6: 498165 | C6: 3009 | D6: 4375 | E6: 2000 | J6: 507549
A7: 2021-06 | B7: 111660 | C7: 7601 | D7: 750 | E7: 1500 | J7: 121511
A8: 2021-07 | B8: 2586275 | C8: 3009 | D8: 500 | E8: 500 | I8: 60000 | J8: 2650284
A9: 2021-08 | B9: 502143 | C9: 3108 | D9: 960 | E9: 1000 | J9: 507211
A10: 2021-09 | B10: 73539 | C10: 3108 | D10: 3200 | E10: 1000 | J10: 80847
A11: 2021-10 | B11: 2362716 | C11: 3009 | D11: 5320 | E11: 2500 | J11: 2373545
A12: 2021-11 | B12: 584076 | C12: 3108 | D12: 7710 | E12: 2500 | I12: 21210 | J12: 618604
A13: 2021-12 | B13: 184344 | C13: 5862 | D13: 8435 | E13: 500 | J13: 199141
A14: 2022-01 | B14: 2394522 | C14: 3108 | D14: 5605 | E14: 1000 | I14: 970 | J14: 2405205
A15: 2022-02 | B15: 655662 | C15: 1800 | J15: 657462
A16: 2022-03 | B16: 76940 | C16: 4116 | D16: 15305 | E16: 3000 | I16: 1116507 | J16: 1215868
A17: 2022-04 | B17: 2955381 | C17: 2794 | D17: 6160 | E17: 4000 | J17: 2968335
A18: 2022-05 | B18: 703893 | C18: 3132 | D18: 5895 | E18: 1500 | J18: 714420
A19: 2022-06 | B19: 85452 | C19: 5205 | D19: 9560 | E19: 2000 | J19: 102217
A20: 2022-07 | B20: 2947852 | C20: 3860 | D20: 5295 | E20: 1500 | I20: 6177 | J20: 2964684
A21: 2022-08 | B21: 835890 | C21: 4545 | D21: 5035 | E21: 2500 | J21: 847970
A22: 2022-09 | B22: 132612 | C22: 4306 | D22: 9090 | E22: 3000 | J22: 149008
A23: 2022-10 | B23: 3223413 | C23: 5431 | D23: 6625 | E23: 2000 | J23: 3237469
A24: 2022-11 | B24: 484833 | C24: 6189 | D24: 7565 | E24: 2500 | J24: 501087
A25: 2022-12 | B25: 68334 | C25: 5704 | D25: 7450 | E25: 3000 | J25: 84488
A26: 2023-01 | B26: 3226644 | C26: 5986 | D26: 5050 | E26: 4000 | F26: 3000 | J26: 3244680
A27: 2023-02 | B27: 524196 | C27: 4888 | D27: 4570 | E27: 3000 | F27: 4000 | J27: 540654
A28: 2023-03 | B28: 138576 | C28: 7214 | D28: 11630 | E28: 3000 | I28: 16720 | J28: 177140
A29: 2023-04 | B29: 2931309 | C29: 6453 | D29: 6025 | E29: 4000 | J29: 2947787
A30: 2023-05 | B30: 855633 | C30: 8250 | D30: 8020 | E30: 1000 | J30: 872903
A31: 2023-06 | B31: 118779 | C31: 8148 | D31: 7290 | E31: 500 | I31: 2400 | J31: 137117
A32: 2023-07 | B32: 3146871 | C32: 7712 | D32: 6815 | E32: 1000 | I32: 28710 | J32: 3191108
A33: 2023-08 | B33: 480417 | C33: 8892 | D33: 4660 | E33: 1000 | I33: 18420 | J33: 513389
A34: 2023-09 | B34: 75744 | C34: 8388 | D34: 20820 | E34: 1000 | I34: 120 | J34: 106072
A35: 2023-10 | B35: 3466637 | C35: 8514 | D35: 8800 | E35: 2500 | J35: 3486451
A36: 2023-11 | B36: 476505 | C36: 9790 | D36: 10400 | E36: 1500 | J36: 498195
A37: 2023-12 | B37: 15528 | C37: 9124 | D37: 11830 | E37: 3500 | F37: 308 | I37: 21900 | J37: 62190
A38: 2024-01 | B38: 3609691 | C38: 9088 | D38: 13310 | E38: 1500 | J38: 3633589
A39: 2024-02 | B39: 284220 | C39: 10032 | D39: 6180 | E39: 1000 | J39: 301432
A40: 2024-03 | B40: 28980 | C40: 8868 | J40: 37848
...

Sheet 議案-外牆修繕
A1: 議案彙整 — 外牆修繕
A2: 外牆磁磚修繕系列 (天幕高空 + 蜘蛛人施工 + 坦茂磁磚採購 + 建築師公會鑑定報告)
A4: ─── 統計（公式自動計算）───
A5: 合計金額 (NT$) | B5: =SUMIFS(支出明細!C:C,支出明細!F:F,"外牆修繕") | D5: ← SUMIFS 公式：sum of C where F='外牆修繕'
A6: 筆數 | B6: =COUNTIF(支出明細!F:F,"外牆修繕") | D6: ← COUNTIF 公式：count of F='外牆修繕'
A7: 期間 | B7: 2025-07 ~ 2026-04 | D7: ← Python pre-compute (min/max month)
A9: ─── 明細（每 cell = 「支出明細」 sheet 對應 row 的公式 reference）───
A10: 月份 | B10: 金額 (NT$) | C10: 工程項目 | D10: 分類 | E10: Section | F10: (支出明細 row #)
A11: =支出明細!A1549 | B11: =支出明細!C1549 | C11: =支出明細!B1549 | D11: =支出明細!D1549 | E11: =支出明細!E1549 | F11: 1549
A12: =支出明細!A1617 | B12: =支出明細!C1617 | C12: =支出明細!B1617 | D12: =支出明細!D1617 | E12: =支出明細!E1617 | F12: 1618
A13: =支出明細!A1578 | B13: =支出明細!C1578 | C13: =支出明細!B1578 | D13: =支出明細!D1578 | E13: =支出明細!E1578 | F13: 1579
A14: =支出明細!A1661 | B14: =支出明細!C1661 | C14: =支出明細!B1661 | D14: =支出明細!D1661 | E14: =支出明細!E1661 | F14: 1662
A15: =支出明細!A1512 | B15: =支出明細!C1512 | C15: =支出明細!B1512 | D15: =支出明細!D1512 | E15: =支出明細!E1512 | F15: 1512
A16: =支出明細!A1858 | B16: =支出明細!C1858 | C16: =支出明細!B1858 | D16: =支出明細!D1858 | E16: =支出明細!E1858 | F16: 1859
A17: =支出明細!A1706 | B17: =支出明細!C1706 | C17: =支出明細!B1706 | D17: =支出明細!D1706 | E17: =支出明細!E1706 | F17: 1707
A18: =支出明細!A1774 | B18: =支出明細!C1774 | C18: =支出明細!B1774 | D18: =支出明細!D1774 | E18: =支出明細!E1774 | F18: 1775
A19: =支出明細!A1702 | B19: =支出明細!C1702 | C19: =支出明細!B1702 | D19: =支出明細!D1702 | E19: =支出明細!E1702 | F19: 1703
A20: =支出明細!A1703 | B20: =支出明細!C1703 | C20: =支出明細!B1703 | D20: =支出明細!D1703 | E20: =支出明細!E1703 | F20: 1704
A21: =支出明細!A1852 | B21: =支出明細!C1852 | C21: =支出明細!B1852 | D21: =支出明細!D1852 | E21: =支出明細!E1852 | F21: 1853
A22: =支出明細!A1631 | B22: =支出明細!C1631 | C22: =支出明細!B1631 | D22: =支出明細!D1631 | E22: =支出明細!E1631 | F22: 1632
A23: =支出明細!A1550 | B23: =支出明細!C1550 | C23: =支出明細!B1550 | D23: =支出明細!D1550 | E23: =支出明細!E1550 | F23: 1550
A24: =支出明細!A1816 | B24: =支出明細!C1816 | C24: =支出明細!B1816 | D24: =支出明細!D1816 | E24: =支出明細!E1816 | F24: 1817
A25: 明細加總（應 = 上方統計 B5） | B25: =SUM(B11:B24)
A26: 差額 (B5 − 明細加總) | B26: =B5-B25 | D26: ← 應為 0；若 ≠ 0 表示 SUMIFS 抓的 row ≠ 明細列出的 row

Sheet 議案-納管
A1: 議案彙整 — 納管
A2: 汙水管路納管工程 (慈濟路人行道納管 + B3 汙水自動控制系統 + 配管 / 抽水 / 雜項)
A4: ─── 統計（公式自動計算）───
A5: 合計金額 (NT$) | B5: =SUMIFS(支出明細!C:C,支出明細!F:F,"納管") | D5: ← SUMIFS 公式：sum of C where F='納管'
A6: 筆數 | B6: =COUNTIF(支出明細!F:F,"納管") | D6: ← COUNTIF 公式：count of F='納管'
A7: 期間 | B7: 2025-04 ~ 2026-06 | D7: ← Python pre-compute (min/max month)
A9: ─── 明細（每 cell = 「支出明細」 sheet 對應 row 的公式 reference）───
A10: 月份 | B10: 金額 (NT$) | C10: 工程項目 | D10: 分類 | E10: Section | F10: (支出明細 row #)
A11: =支出明細!A1503 | B11: =支出明細!C1503 | C11: =支出明細!B1503 | D11: =支出明細!D1503 | E11: =支出明細!E1503 | F11: 1503
A12: =支出明細!A1516 | B12: =支出明細!C1516 | C12: =支出明細!B1516 | D12: =支出明細!D1516 | E12: =支出明細!E1516 | F12: 1516
A13: =支出明細!A1864 | B13: =支出明細!C1864 | C13: =支出明細!B1864 | D13: =支出明細!D1864 | E13: =支出明細!E1864 | F13: 1865
A14: =支出明細!A1856 | B14: =支出明細!C1856 | C14: =支出明細!B1856 | D14: =支出明細!D1856 | E14: =支出明細!E1856 | F14: 1857
A15: =支出明細!A1446 | B15: =支出明細!C1446 | C15: =支出明細!B1446 | D15: =支出明細!D1446 | E15: =支出明細!E1446 | F15: 1446
A16: =支出明細!A1746 | B16: =支出明細!C1746 | C16: =支出明細!B1746 | D16: =支出明細!D1746 | E16: =支出明細!E1746 | F16: 1747
A17: =支出明細!A1416 | B17: =支出明細!C1416 | C17: =支出明細!B1416 | D17: =支出明細!D1416 | E17: =支出明細!E1416 | F17: 1416
A18: =支出明細!A1779 | B18: =支出明細!C1779 | C18: =支出明細!B1779 | D18: =支出明細!D1779 | E18: =支出明細!E1779 | F18: 1780
A19: =支出明細!A1413 | B19: =支出明細!C1413 | C19: =支出明細!B1413 | D19: =支出明細!D1413 | E19: =支出明細!E1413 | F19: 1413
A20: 明細加總（應 = 上方統計 B5） | B20: =SUM(B11:B19)
A21: 差額 (B5 − 明細加總) | B21: =B5-B20 | D21: ← 應為 0；若 ≠ 0 表示 SUMIFS 抓的 row ≠ 明細列出的 row

Sheet 議案-電梯
A1: 議案彙整 — 電梯
A2: 電梯議案 (崇友月保養費 + 變頻器/控制板/HCD顯示器/微壓按鈕 等零件修繕) — 排除電梯專用款撥補
A4: ─── 統計（公式自動計算）───
A5: 合計金額 (NT$) | B5: =SUMIFS(支出明細!C:C,支出明細!F:F,"電梯") | D5: ← SUMIFS 公式：sum of C where F='電梯'
A6: 筆數 | B6: =COUNTIF(支出明細!F:F,"電梯") | D6: ← COUNTIF 公式：count of F='電梯'
A7: 期間 | B7: 2021-01 ~ 2026-04 | D7: ← Python pre-compute (min/max month)
A9: ─── 明細（每 cell = 「支出明細」 sheet 對應 row 的公式 reference）───
A10: 月份 | B10: 金額 (NT$) | C10: 工程項目 | D10: 分類 | E10: Section | F10: (支出明細 row #)
A11: =支出明細!A687 | B11: =支出明細!C687 | C11: =支出明細!B687 | D11: =支出明細!D687 | E11: =支出明細!E687 | F11: 687
A12: =支出明細!A1176 | B12: =支出明細!C1176 | C12: =支出明細!B1176 | D12: =支出明細!D1176 | E12: =支出明細!E1176 | F12: 1176
A13: =支出明細!A641 | B13: =支出明細!C641 | C13: =支出明細!B641 | D13: =支出明細!D641 | E13: =支出明細!E641 | F13: 641
A14: =支出明細!A800 | B14: =支出明細!C800 | C14: =支出明細!B800 | D14: =支出明細!D800 | E14: =支出明細!E800 | F14: 800
A15: =支出明細!A1434 | B15: =支出明細!C1434 | C15: =支出明細!B1434 | D15: =支出明細!D1434 | E15: =支出明細!E1434 | F15: 1434
A16: =支出明細!A1608 | B16: =支出明細!C1608 | C16: =支出明細!B1608 | D16: =支出明細!D1608 | E16: =支出明細!E1608 | F16: 1609
A17: =支出明細!A168 | B17: =支出明細!C168 | C17: =支出明細!B168 | D17: =支出明細!D168 | E17: =支出明細!E168 | F17: 168
A18: =支出明細!A1443 | B18: =支出明細!C1443 | C18: =支出明細!B1443 | D18: =支出明細!D1443 | E18: =支出明細!E1443 | F18: 1443
A19: =支出明細!A1175 | B19: =支出明細!C1175 | C19: =支出明細!B1175 | D19: =支出明細!D1175 | E19: =支出明細!E1175 | F19: 1175
A20: =支出明細!A1472 | B20: =支出明細!C1472 | C20: =支出明細!B1472 | D20: =支出明細!D1472 | E20: =支出明細!E1472 | F20: 1472
A21: =支出明細!A1541 | B21: =支出明細!C1541 | C21: =支出明細!B1541 | D21: =支出明細!D1541 | E21: =支出明細!E1541 | F21: 1541
A22: =支出明細!A1179 | B22: =支出明細!C1179 | C22: =支出明細!B1179 | D22: =支出明細!D1179 | E22: =支出明細!E1179 | F22: 1179
A23: =支出明細!A1539 | B23: =支出明細!C1539 | C23: =支出明細!B1539 | D23: =支出明細!D1539 | E23: =支出明細!E1539 | F23: 1539
A24: =支出明細!A1408 | B24: =支出明細!C1408 | C24: =支出明細!B1408 | D24: =支出明細!D1408 | E24: =支出明細!E1408 | F24: 1408
A25: =支出明細!A1614 | B25: =支出明細!C1614 | C25: =支出明細!B1614 | D25: =支出明細!D1614 | E25: =支出明細!E1614 | F25: 1615
A26: =支出明細!A1471 | B26: =支出明細!C1471 | C26: =支出明細!B1471 | D26: =支出明細!D1471 | E26: =支出明細!E1471 | F26: 1471
A27: =支出明細!A473 | B27: =支出明細!C473 | C27: =支出明細!B473 | D27: =支出明細!D473 | E27: =支出明細!E473 | F27: 473
A28: =支出明細!A1114 | B28: =支出明細!C1114 | C28: =支出明細!B1114 | D28: =支出明細!D1114 | E28: =支出明細!E1114 | F28: 1114
A29: =支出明細!A131 | B29: =支出明細!C131 | C29: =支出明細!B131 | D29: =支出明細!D131 | E29: =支出明細!E131 | F29: 131
A30: =支出明細!A108 | B30: =支出明細!C108 | C30: =支出明細!B108 | D30: =支出明細!D108 | E30: =支出明細!E108 | F30: 108
A31: =支出明細!A1694 | B31: =支出明細!C1694 | C31: =支出明細!B1694 | D31: =支出明細!D1694 | E31: =支出明細!E1694 | F31: 1695
A32: =支出明細!A1806 | B32: =支出明細!C1806 | C32: =支出明細!B1806 | D32: =支出明細!D1806 | E32: =支出明細!E1806 | F32: 1807
A33: =支出明細!A72 | B33: =支出明細!C72 | C33: =支出明細!B72 | D33: =支出明細!D72 | E33: =支出明細!E72 | F33: 72
A34: =支出明細!A73 | B34: =支出明細!C73 | C34: =支出明細!B73 | D34: =支出明細!D73 | E34: =支出明細!E73 | F34: 73
A35: =支出明細!A965 | B35: =支出明細!C965 | C35: =支出明細!B965 | D35: =支出明細!D965 | E35: =支出明細!E965 | F35: 965
A36: =支出明細!A447 | B36: =支出明細!C447 | C36: =支出明細!B447 | D36: =支出明細!D447 | E36: =支出明細!E447 | F36: 447
A37: =支出明細!A799 | B37: =支出明細!C799 | C37: =支出明細!B799 | D37: =支出明細!D799 | E37: =支出明細!E799 | F37: 799
A38: =支出明細!A388 | B38: =支出明細!C388 | C38: =支出明細!B388 | D38: =支出明細!D388 | E38: =支出明細!E388 | F38: 388
A39: =支出明細!A332 | B39: =支出明細!C332 | C39: =支出明細!B332 | D39: =支出明細!D332 | E39: =支出明細!E332 | F39: 332
A40: =支出明細!A1178 | B40: =支出明細!C1178 | C40: =支出明細!B1178 | D40: =支出明細!D1178 | E40: =支出明細!E1178 | F40: 1178
A41: =支出明細!A1409 | B41: =支出明細!C1409 | C41: =支出明細!B1409 | D41: =支出明細!D1409 | E41: =支出明細!E1409 | F41: 1409
A42: =支出明細!A1671 | B42: =支出明細!C1671 | C42: =支出明細!B1671 | D42: =支出明細!D1671 | E42: =支出明細!E1671 | F42: 1672
...

Sheet 帳戶餘額矩陣
A1: 帳戶 | B1: 2021-01 期末 | C1: 2021-02 期末 | D1: 2021-03 期末 | E1: 2021-04 期末 | F1: 2021-05 期末 | G1: 2021-06 期末 | H1: 2021-07 期末 | I1: 2021-08 期末 | J1: 2021-09 期末 | K1: 2021-10 期末 | L1: 2021-11 期末 | M1: 2021-12 期末 | N1: 2022-01 期末 | O1: 2022-02 期末 | P1: 2022-03 期末 | Q1: 2022-04 期末 | R1: 2022-05 期末 | S1: 2022-06 期末 | T1: 2022-07 期末 | U1: 2022-08 期末 | V1: 2022-09 期末 | W1: 2022-10 期末 | X1: 2022-11 期末 | Y1: 2022-12 期末 | Z1: 2023-01 期末 | AA1: 2023-02 期末 | AB1: 2023-03 期末 | AC1: 2023-04 期末 | AD1: 2023-05 期末 | AE1: 2023-06 期末 | AF1: 2023-07 期末 | AG1: 2023-08 期末 | AH1: 2023-09 期末 | AI1: 2023-10 期末 | AJ1: 2023-11 期末 | AK1: 2023-12 期末 | AL1: 2024-01 期末 | AM1: 2024-02 期末 | AN1: 2024-03 期末 | AO1: 2024-04 期末 | AP1: 2024-05 期末 | AQ1: 2024-06 期末 | AR1: 2024-07 期末 | AS1: 2024-08 期末 | AT1: 2024-09 期末 | AU1: 2024-10 期末 | AV1: 2024-11 期末 | AW1: 2024-12 期末 | AX1: 2025-01 期末 | AY1: 2025-02 期末 | AZ1: 2025-03 期末 | BA1: 2025-04 期末 | BB1: 2025-05 期末 | BC1: 2025-06 期末 | BD1: 2025-07 期末 | BE1: 2025-08 期末 | BF1: 2025-09 期末 | BG1: 2025-10 期末 | BH1: 2025-11 期末 | BI1: 2025-12 期末 | BJ1: 2026-01 期末 | BK1: 2026-02 期末 | BL1: 2026-03 期末 | BM1: 2026-04 期末
A2: 元大-充電樁 | BM2: 1751560
A3: 元大-管理費 | B3: 11050941 | C3: 9157051 | D3: 7997326 | E3: 9348204 | F3: 8771140 | G3: 7522776 | H3: 8848852 | I3: 8430866 | J3: 6877926 | K3: 8112288 | L3: 7031183 | M3: 6115928 | N3: 7160287 | O3: 6719611 | P3: 5702708 | Q3: 7546295 | R3: 7199409 | S3: 6315212 | T3: 8280329 | U3: 8136545 | V3: 7338105 | W3: 9132806 | X3: 8457053 | Y3: 7405360 | Z3: 9288384 | AA3: 8162372 | AB3: 7147349 | AC3: 8996801 | AD3: 8817812 | AE3: 7818200 | AF3: 9876163 | AG3: 9033289 | AH3: 8071947 | AI3: 10477719 | AJ3: 9827578 | AK3: 8359517 | AL3: 10772367 | AM3: 9961477 | AN3: 8747981 | AO3: 10507404 | AP3: 10127658 | AQ3: 8787799 | AR3: 10879125 | AS3: 10006791 | AT3: 8504284 | AU3: 10826821 | AV3: 9950090 | AW3: 8667153 | AX3: 9368331 | AY3: 10906768 | AZ3: 9730061 | BA3: 10365084 | BB3: 9995112 | BC3: 8727581 | BD3: 7159519 | BE3: 5426677 | BF3: 3062620 | BG3: 3055046 | BH3: 2491599 | BI3: 1682704 | BJ3: 2663490 | BK3: 1796297 | BL3: 1467895 | BM3: 4308271
A4: 元大-管理費(裝保金暫收款) | BM4: 80000
A5: 元大-電梯 | B5: 2225479 | C5: 2277084 | D5: 2328175 | E5: 2379383 | F5: 2430552 | G5: 2481785 | H5: 2532954 | I5: 2584162 | J5: 2635370 | K5: 2686539 | L5: 2737747 | M5: 2788956 | N5: 2840164 | O5: 2513372 | P5: 2564463 | Q5: 2615671 | R5: 2666840 | S5: 2718131 | T5: 2769300 | U5: 2820508 | V5: 2871716 | W5: 2922885 | X5: 2974093 | Y5: 3026380 | Z5: 3077588 | AA5: 2663796 | AB5: 2715764 | AC5: 2767942 | AD5: 2820050 | AE5: 2874626 | AF5: 2926734 | AG5: 2978912 | AH5: 2511090 | AI5: 2563198 | AJ5: 2615376 | AK5: 2670019 | AL5: 2722197 | AM5: 2254375 | AN5: 2306592 | AO5: 2358962 | AP5: 2411255 | AQ5: 2465548 | AR5: 2517841 | AS5: 2570211 | AT5: 2622581 | AU5: 2154874 | AV5: 2209537 | AW5: 2213973 | AX5: 2313973 | AY5: 2316343 | AZ5: 2368656 | BA5: 2421217 | BB5: 910548 | BC5: 912597 | BD5: 912597 | BM5: 1445251
A6: 台銀-公共基金(定存) | B6: 5915617 | C6: 5918333 | D6: 5921049 | E6: 5923765 | F6: 5926481 | G6: 5929580 | H6: 5932296 | I6: 5935012 | J6: 5937728 | K6: 5940444 | L6: 5943160 | M6: 5946265 | N6: 5948981 | O6: 5951697 | P6: 5954413 | Q6: 5957685 | R6: 5961237 | S6: 5965383 | T6: 5969211 | U6: 5973179 | V6: 5977147 | W6: 5981307 | X6: 5985691 | Y6: 5992704 | Z6: 5997392 | AA6: 6002192 | AB6: 6006992 | AC6: 6011988 | AD6: 6017204 | AE6: 6027566 | AF6: 6032782 | AG6: 6037998 | AH6: 6043214 | AI6: 6048430 | AJ6: 6053646 | AK6: 6064801 | AL6: 6070017 | AM6: 6075233 | AN6: 6080449 | AO6: 6085889 | AP6: 6091521 | AQ6: 6103831 | AR6: 6109463 | AS6: 6115095 | AT6: 6120727 | AU6: 6126359 | AV6: 6131991 | AW6: 6145116 | AX6: 6150748 | AY6: 6156380 | AZ6: 6162012 | BA6: 6167644 | BB6: 6173276 | BC6: 6186505 | BD6: 4000000 | BE6: 4000000 | BF6: 4000000 | BG6: 4000000 | BH6: 4000000 | BI6: 4000000 | BJ6: 4000000 | BK6: 4000000 | BL6: 4000000 | BM6: 4000000
A7: 台銀-活存 | BE7: 2197769 | BF7: 2203401 | BG7: 2209033 | BH7: 2214665 | BI7: 2228082 | BJ7: 2233714 | BK7: 2239346 | BL7: 2244978 | BM7: 11224
A8: 應收-AED押金 | B8: 10798 | C8: 20000 | D8: 20000 | E8: 20000 | F8: 20000 | G8: 20000 | H8: 20000 | I8: 4000 | J8: 4000 | K8: 4000 | L8: 4000 | M8: 4000 | N8: 4000 | O8: 4000 | P8: 4000 | Q8: 4000 | R8: 4000 | S8: 4000 | T8: 4000 | U8: 4000 | V8: 4000 | W8: 4000 | X8: 4000 | Y8: 4000 | Z8: 4000 | AA8: 4000 | AB8: 4000 | AC8: 4000 | AD8: 4000 | AE8: 4000 | AF8: 4000 | AG8: 4000 | AH8: 4000 | AI8: 4000 | AJ8: 4000 | AK8: 4000 | AL8: 4000 | AM8: 4000 | AN8: 4000 | AO8: 4000 | AP8: 4000 | AQ8: 4000 | AR8: 4000 | AS8: 4000 | AT8: 4000 | AU8: 4000 | AV8: 4000 | AW8: 4000 | AX8: 4000 | AY8: 4000 | AZ8: 4000 | BA8: 4000 | BB8: 4000 | BC8: 4000 | BD8: 10000 | BE8: 10000 | BF8: 10000 | BG8: 10000 | BH8: 10000 | BI8: 10000 | BJ8: 10000 | BK8: 10000 | BL8: 10000 | BM8: 10000
A9: 零用金 | BM9: 17444
A10: 全帳戶月末合計 | B10: 19202835 | C10: 17372468 | D10: 16266550 | E10: 17671352 | F10: 17148173 | G10: 15954141 | H10: 17334102 | I10: 16954040 | J10: 15455024 | K10: 16743271 | L10: 15716090 | M10: 14855149 | N10: 15953432 | O10: 15188680 | P10: 14225584 | Q10: 16123651 | R10: 15831486 | S10: 15002726 | T10: 17022840 | U10: 16934232 | V10: 16190968 | W10: 18040998 | X10: 17420837 | Y10: 16428444 | Z10: 18367364 | AA10: 16832360 | AB10: 15874105 | AC10: 17780731 | AD10: 17659066 | AE10: 16724392 | AF10: 18839679 | AG10: 18054199 | AH10: 16630251 | AI10: 19093347 | AJ10: 18500600 | AK10: 17098337 | AL10: 19568581 | AM10: 18295085 | AN10: 17139022 | AO10: 18956255 | AP10: 18634434 | AQ10: 17361178 | AR10: 19510429 | AS10: 18696097 | AT10: 17251592 | AU10: 19112054 | AV10: 18295618 | AW10: 17030242 | AX10: 17837052 | AY10: 19383491 | AZ10: 18264729 | BA10: 18957945 | BB10: 17082936 | BC10: 15830683 | BD10: 12082116 | BE10: 11634446 | BF10: 9276021 | BG10: 9274079 | BH10: 8716264 | BI10: 7920786 | BJ10: 8907204 | BK10: 8045643 | BL10: 7722873 | BM10: 11623750

Sheet 帳戶月度明細
A1: 月份 | B1: 帳戶 | C1: 上期餘額 | D1: 本月收入 | E1: 本月支出 | F1: 期末餘額
A2: 2021-01 | B2: 元大-管理費 | C2: 10096540 | D2: 954401 | E2: 0 | F2: 11050941
A3: 2021-01 | B3: 台銀-公共基金(定存) | C3: 5912901 | D3: 2716 | E3: 0 | F3: 5915617
A4: 2021-01 | B4: 元大-電梯 | C4: 2173874 | D4: 51605 | E4: 0 | F4: 2225479
A5: 2021-01 | B5: 應收-AED押金 | C5: 15923 | D5: 0 | E5: 5125 | F5: 10798
A6: 2021-01 | B6: ↳ 2021-01 小計 (4 帳) | C6: 18199238 | D6: 1008722 | E6: 5125 | F6: 19202835
A7: 2021-02 | B7: 元大-管理費 | C7: 11050941 | D7: 0 | E7: 1893890 | F7: 9157051
A8: 2021-02 | B8: 台銀-公共基金(定存) | C8: 5915617 | D8: 2716 | E8: 0 | F8: 5918333
A9: 2021-02 | B9: 元大-電梯 | C9: 2225479 | D9: 51605 | E9: 0 | F9: 2277084
A10: 2021-02 | B10: 應收-AED押金 | C10: 10798 | D10: 9202 | E10: 0 | F10: 20000
A11: 2021-02 | B11: ↳ 2021-02 小計 (4 帳) | C11: 19202835 | D11: 63523 | E11: 1893890 | F11: 17372468
A12: 2021-03 | B12: 元大-管理費 | C12: 9157051 | D12: 0 | E12: 1159725 | F12: 7997326
A13: 2021-03 | B13: 台銀-公共基金(定存) | C13: 5918333 | D13: 2716 | E13: 0 | F13: 5921049
... A325: 2026-04 | B325: ↳ 2026-04 小計 (8 帳) | C325: 11025447 | D325: 5707536 | E325: 5109233 | F325: 11623750

Sheet 專款明細
A1: 月份 | B1: 專款 | C1: 項目類型 | D1: 科目 / 摘要 | E1: 金額
A2: 2022-03 | B2: 充電樁 | C2: 上期餘額 | E2: 0
A3: 2022-03 | B3: 充電樁 | C3: 收入 | D3: 自111年Q2季起 每季應收管理費$3,857,907 | E3: 2
A4: 2022-03 | B4: 充電樁 | C4: 本月小計 | D4: 收 2 / 支 0 | E4: 2
A5: 2022-03 | B5: 電梯 | C5: 上期餘額 | E5: 0
A6: 2022-03 | B6: 電梯 | C6: 收入 | D6: 自111年Q2季起 每季應收管理費$3,857,907 | E6: 2
A7: 2022-03 | B7: 電梯 | C7: 本月小計 | D7: 收 2 / 支 0 | E7: 2
A8: 2022-04 | B8: 充電樁 | C8: 上期餘額 | E8: 0
A9: 2022-04 | B9: 充電樁 | C9: 收入 | D9: 自111年Q2季起 每季應收管理費$3,857,907 | E9: 1
A10: 2022-04 | B10: 充電樁 | C10: 本月小計 | D10: 收 1 / 支 0 | E10: 1
A11: 2022-04 | B11: 電梯 | C11: 上期餘額 | E11: 0
A12: 2022-04 | B12: 電梯 | C12: 收入 | D12: 自111年Q2季起 每季應收管理費$3,857,907 | E12: 1
A13: 2022-04 | B13: 電梯 | C13: 本月小計 | D13: 收 1 / 支 0 | E13: 1
A14: 2022-05 | B14: 充電樁 | C14: 上期餘額 | E14: 0
A15: 2022-05 | B15: 充電樁 | C15: 收入 | D15: 自111年Q2季起 每季應收管理費$3,857,907 | E15: 1
A16: 2022-05 | B16: 充電樁 | C16: 本月小計 | D16: 收 1 / 支 0 | E16: 1
A17: 2022-05 | B17: 電梯 | C17: 上期餘額 | E17: 0
A18: 2022-05 | B18: 電梯 | C18: 收入 | D18: 自111年Q2季起 每季應收管理費$3,857,907 | E18: 1
A19: 2022-05 | B19: 電梯 | C19: 本月小計 | D19: 收 1 / 支 0 | E19: 1
A20: 2022-06 | B20: 充電樁 | C20: 上期餘額 | E20: 4145183
A21: 2022-06 | B21: 充電樁 | C21: 收入 | D21: 自111年Q2季起 每季應收管理費$3,857,907 | E21: 12
A22: 2022-06 | B22: 充電樁 | C22: 本月小計 | D22: 收 12 / 支 0 | E22: 4145195
A23: 2022-06 | B23: 電梯 | C23: 上期餘額 | E23: 4145183
A24: 2022-06 | B24: 電梯 | C24: 收入 | D24: 自111年Q2季起 每季應收管理費$3,857,907 | E24: 12
A25: 2022-06 | B25: 電梯 | C25: 本月小計 | D25: 收 12 / 支 0 | E25: 4145195
A26: 2022-07 | B26: 充電樁 | C26: 上期餘額 | E26: 4129086
A27: 2022-07 | B27: 充電樁 | C27: 收入 | D27: 自111年Q2季起 每季應收管理費$3,857,907 | E27: 4
A28: 2022-07 | B28: 充電樁 | C28: 本月小計 | D28: 收 4 / 支 0 | E28: 4129090
A29: 2022-07 | B29: 電梯 | C29: 上期餘額 | E29: 4129086
A30: 2022-07 | B30: 電梯 | C30: 收入 | D30: 自111年Q2季起 每季應收管理費$3,857,907 | E30: 4
A31: 2022-07 | B31: 電梯 | C31: 本月小計 | D31: 收 4 / 支 0 | E31: 4129090
A32: 2022-08 | B32: 充電樁 | C32: 上期餘額 | E32: 4129086
A33: 2022-08 | B33: 充電樁 | C33: 本月小計 | D33: 收 0 / 支 0 | E33: 4129086
A34: 2022-08 | B34: 電梯 | C34: 上期餘額 | E34: 4129086
A35: 2022-08 | B35: 電梯 | C35: 本月小計 | D35: 收 0 / 支 0 | E35: 4129086
A36: 2022-09 | B36: 充電樁 | C36: 上期餘額 | E36: 4129086
A37: 2022-09 | B37: 充電樁 | C37: 本月小計 | D37: 收 0 / 支 0 | E37: 4129086
A38: 2022-09 | B38: 電梯 | C38: 上期餘額 | E38: 4129086
A39: 2022-09 | B39: 電梯 | C39: 本月小計 | D39: 收 0 / 支 0 | E39: 4129086
A40: 2022-10 | B40: 充電樁 | C40: 上期餘額 | E40: 4239086
...

Sheet 暫收款明細
A1: 月份 | B1: 類型 | C1: 日期 | D1: 戶別 | E1: 金額
A2: 2021-02 | B2: 收暫收 | C2: 2021-02-17 | D2: Q23 | E2: 20000
A3: 2021-02 | B3: 退暫收 | D3: H4 | E3: 80000
A4: 2021-02 | B4: 收暫收 | C4: 2021-02-25 | D4: K17 | E4: 20000
A5: 2021-02 | B5: 收暫收 | C5: 總計 | E5: 40000
A6: 2021-02 | B6: 收暫收 | C6: 6000000 | E6: 3157051
A7: 2021-02 | B7: 退暫收 | E7: 17382468
A8: 2021-02 | B8: 收暫收 | C8: 4000000 | E8: 1915617
A9: 2021-02 | B9: 收暫收 | C9: 1800000 | E9: 475479
A10: 2023-12 | B10: 收暫收 | C10: 4 | D10: 11 | E10: 414
A11: 2023-12 | B11: 收暫收 | C11: 28437 | D11: 97723 | E11: 3825979
A12: 2024-01 | B12: 收暫收 | C12: Q1 | E12: 40
A13: 2024-01 | B13: 收暫收 | C13: 342471 | E13: 350247
A14: 2024-02 | B14: 收暫收 | C14: Q1 | E14: 8
A15: 2024-02 | B15: 收暫收 | C15: 66411 | E15: 74187
A16: 2024-03 | B16: 收暫收 | C16: Q2 | E16: 4
A17: 2024-03 | B17: 收暫收 | E17: 29271
A18: 2024-04 | B18: 收暫收 | C18: Q2 | E18: 91
A19: 2024-04 | B19: 收暫收 | C19: 802296 | E19: 815361
A20: 2024-05 | B20: 收暫收 | C20: 2 | E20: 16
A21: 2024-05 | B21: 收暫收 | C21: 13065 | E21: 137088
A22: 2024-06 | B22: 收暫收 | C22: 2 | E22: 5
A23: 2024-06 | B23: 收暫收 | C23: 13065 | E23: 36102
A24: 2024-07 | B24: 收暫收 | C24: 57 | E24: 59
A25: 2024-07 | B25: 收暫收 | C25: 516762 | E25: 532284
A26: 2025-06 | B26: 收暫收 | C26: S11 | D26: 2025-06-27 00:00:00 | E26: 80000
A27: 2025-06 | B27: 退暫收 | E27: 140000
A28: 2025-06 | B28: 收暫收 | C28: 總計 | E28: 80000
A29: 2025-06 | B29: 收暫收 | C29: 5000000 | E29: 3727581
A30: 2025-06 | B30: 退暫收 | E30: 15860683
A31: 2025-06 | B31: 收暫收 | C31: 4000000 | E31: 2173276
A32: 2025-08 | B32: 收暫收 | C32: 2025-08-14 | D32: B13 | E32: 20000
A33: 2025-08 | B33: 退暫收 | E33: 160000
A34: 2025-08 | B34: 收暫收 | C34: 總計 | E34: 20000
A35: 2025-08 | B35: 收暫收 | C35: 45 | D35: 33 | E35: 66
A36: 2025-09 | B36: 收暫收 | C36: 2025-09-11 | D36: S8 | E36: 80000
A37: 2025-09 | B37: 退暫收 | E37: 220000
A38: 2025-09 | B38: 收暫收 | C38: 總計 | E38: 80000
A39: 2025-09 | B39: 收暫收 | C39: 45 | D39: 33 | E39: 54
A40: 2025-10 | B40: 退暫收 | E40: 200000
...

Sheet 管理費未繳統計
A1: 月份 | B1: 季別 | C1: 未繳戶數 | D1: 未繳金額
A2: 2021-01 | B2: Q1 | C2: 0 | D2: 0
A3: 2021-01 | B3: Q2 | C3: 0 | D3: 0
A4: 2021-01 | B4: Q3 | C4: 1 | D4: 4350
A5: 2021-01 | B5: Q4 | C5: 1 | D5: 4350
A6: 2021-01 | B6: Q1 | C6: 125 | D6: 924324
A7: 2021-02 | B7: Q1 | C7: 8 | D7: 62322
A8: 2021-02 | B8: Q2 | C8: 0 | D8: 0
A9: 2021-02 | B9: Q3 | C9: 0 | D9: 0
A10: 2021-02 | B10: Q4 | C10: 0 | D10: 0
A11: 2021-03 | B11: Q1 | C11: 5 | D11: 33690
A12: 2021-03 | B12: Q2 | C12: 412 | D12: 3036234
A13: 2021-03 | B13: Q3 | C13: 0 | D13: 0
... A214: 2026-04 | B214: Q2 | C214: 51 | D214: 576294

Sheet 議案-主鋼索更換
A1: 議案 — 電梯主鋼索更換歷史 (10 次)
A2: 資料來源: 電梯專戶明細 sheet (世界島電梯專戶(威) 0413-僅電梯專戶表格.xlsx)
A4: ◆ 統計
A5: 總次數 | B5: 10 次
A6: 累計支出 | B6: NT$ 4,725,550
A7: 平均每次 | B7: NT$ 472,555
A8: 時間區間 | B8: 2020-10-06 ~ 2025-07-21 (橫跨 6 年)
A9: 峰值年度 | B9: 2025 年: 4 條 ($2,080,000)
A11: ◆ 逐筆明細 (依時間順序)
A12: # | B12: 民國日期 | C12: 西元日期 | D12: 主鋼索編號 | E12: 金額 | F12: 備註
A13: 1 | B13: 109.10.06 | C13: 2020-10-06 | D13: 主鋼索1 | E13: 242550 | F13: 首次更換，金額較低 (可能為小範圍維修而非全套)
A14: 2 | B14: 111.02.24 | C14: 2022-02-24 | D14: 主鋼索3 | E14: 378000 | F14: 同步整理檔已記錄 (鑫禾機電)
A15: 3 | B15: 112.02.24 | C15: 2023-02-24 | D15: 主鋼索2 | E15: 465000 | F15: 次年更換編號 2
A16: 4 | B16: 112.09.27 | C16: 2023-09-27 | D16: 主鋼索8 | E16: 520000 | F16: 單價跳升至 52 萬
A17: 5 | B17: 113.02.26 | C17: 2024-02-26 | D17: 主鋼索6 | E17: 520000
A18: 6 | B18: 113.10.28 | C18: 2024-10-28 | D18: 主鋼索10 | E18: 520000 | F18: ⚠️ 物業交接前最後一筆
A19: 7 | B19: 114.05.02 | C19: 2025-05-02 | D19: 主鋼索5 | E19: 520000 | F19: 🔴 同日 3 條 (5、4、7)，合計 $1,560,000，可能配合 解定存 $1.8M 進行
A20: 8 | B20: 114.05.02 | C20: 2025-05-02 | D20: 主鋼索4 | E20: 520000 | F20: 🔴 同上
A21: 9 | B21: 114.05.02 | C21: 2025-05-02 | D21: 主鋼索7 | E21: 520000 | F21: 🔴 同上
A22: 10 | B22: 114.07.21 | C22: 2025-07-21 | D22: 主鋼索9 | E22: 520000 | F22: 整理檔 2025-07 元大-電梯 變動漏記 — 帳上仍顯示 912,597
A23: 合計 | D23: 10 次 | E23: 4725550
A25: ◆ 觀察與建議
A26: • 主鋼索更換從 2020 年首次後，逐漸密集。2022/2023/2024 每年 1-3 條，2025 年 5 月一次 3 條。
A27: • 平均每年從電梯專戶撥出 ~$800K 用於主鋼索更換 (2022 後)，遠超月撥款 50K-100K 的累積速度。
A28: • 2025-05 同日 3 條 + 2025-07 1 條 = 共 4 條 ($2.08M)，與 解定存 1,799,331 時間吻合 — 可能是規劃性維修。
A29: • 期末活儲 1,345,251 (2026-03)，定存已全部解約。資金水位需注意。
A30: • 整理檔 2025-07 元大-電梯 變動漏記 NT$ 320,000 (該補入)。

Sheet 電梯專戶明細
A1: 民國日期 | B1: 西元日期 | C1: 月份 | D1: 收入 | E1: 支出 | F1: 餘額 | G1: 說明 | H1: 分類
A2: 108.04.12 | B2: 2019-04-12 | C2: 2019-04 | D2: 50000 | F2: 50000 | G2: 108/04管理費撥款電梯專戶 | H2: 管理費撥款
A3: 108.04.12 | B3: 2019-04-12 | C3: 2019-04 | D3: 1250000 | F3: 1300000 | G3: 昌禾提撥款 | H3: 昌禾初始提撥
A4: 108.05.09 | B4: 2019-05-09 | C4: 2019-05 | D4: 50000 | F4: 1350000 | G4: 108/05管理費撥款電梯專戶 | H4: 管理費撥款
A5: 108.06.04 | B5: 2019-06-04 | C5: 2019-06 | D5: 50000 | F5: 1400000 | G5: 108/06管理費撥款電梯專戶 | H5: 管理費撥款
A6: 108.06.21 | B6: 2019-06-21 | C6: 2019-06 | D6: 129 | F6: 1400129 | G6: 存款息 | H6: 存款利息
A7: 108.07.08 | B7: 2019-07-08 | C7: 2019-07 | D7: 50000 | F7: 1450129 | G7: 108/07管理費撥款電梯專戶 | H7: 管理費撥款
A8: 108.07.09 | B8: 2019-07-09 | C8: 2019-07 | D8: 100000 | F8: 1550129 | G8: 108/07管理費重複撥款電梯專戶 | H8: 其他
A9: 108.08.06 | B9: 2019-08-06 | C9: 2019-08 | D9: 50000 | F9: 1600129 | G9: 108/08管理費撥款電梯專戶 | H9: 管理費撥款
A10: 108.09.09 | B10: 2019-09-09 | C10: 2019-09 | D10: 50000 | F10: 1650129 | G10: 108/09管理費撥款電梯專戶 | H10: 管理費撥款
A11: 108.10.04 | B11: 2019-10-04 | C11: 2019-10 | D11: 50000 | F11: 1700129 | G11: 108/10管理費撥款電梯專戶 | H11: 管理費撥款
A12: 108.11.08 | B12: 2019-11-08 | C12: 2019-11 | D12: 50000 | F12: 1750129 | G12: 108/11管理費撥款電梯專戶 | H12: 管理費撥款
A13: 108.12.10 | B13: 2019-12-10 | C13: 2019-12 | D13: 50000 | F13: 1800129 | G13: 108/12管理費撥款電梯專戶 | H13: 管理費撥款
... A16: 109.01.21 | B16: 2020-01-21 | C16: 2020-01 | D16: 50000 | F16: 1900539 | G16: 109/02管理費撥款電梯專戶 | H16: 管理費撥款
A17: 109.02.04 | B17: 2020-02-04 | C17: 2020-02 | E17: 1800000 | F17: 100539 | G17: 轉定存 | H17: 轉定存
A18: 109.03.04 | B18: 2020-03-04 | C18: 2020-03 | D18: 1502 | F18: 102041 | G18: 存款息 | H18: 存款利息
A19: 109.03.06 | B19: 2020-03-06 | C19: 2020-03 | D19: 50000 | F19: 152041 | G19: 109/03管理費撥款電梯專戶 | H19: 管理費撥款
A20: 109.04.06 | B20: 2020-04-06 | C20: 2020-04 | D20: 1605 | F20: 153646 | G20: 存款息 | H20: 存款利息
A21: 109.04.07 | B21: 2020-04-07 | C21: 2020-04 | D21: 50000 | F21: 203646 | G21: 109/04管理費撥款電梯專戶 | H21: 管理費撥款
A22: 109.05.04 | B22: 2020-05-04 | C22: 2020-05 | D22: 1553 | F22: 205199 | G22: 存款息 | H22: 存款利息
A23: 109.05.04 | B23: 2020-05-04 | C23: 2020-05 | D23: 50000 | F23: 255199 | G23: 109/05管理費撥款電梯專戶 | H23: 管理費撥款
A24: 109.06.01 | B24: 2020-06-01 | C24: 2020-06 | D24: 50000 | F24: 305199 | G24: 109/06管理費撥款電梯專戶 | H24: 管理費撥款
A25: 109.06.04 | B25: 2020-06-04 | C25: 2020-06 | D25: 1605 | F25: 306804 | G25: 存款息 | H25: 存款利息
A26: 109.06.21 | B26: 2020-06-21 | C26: 2020-06 | D26: 128 | F26: 306932 | G26: 存款息 | H26: 存款利息
A27: 109.07.06 | B27: 2020-07-06 | C27: 2020-07 | D27: 1553 | F27: 308485 | G27: 存款息 | H27: 存款利息
A28: 109.07.08 | B28: 2020-07-08 | C28: 2020-07 | D28: 50000 | F28: 358485 | G28: 109/07管理費撥款電梯專戶 | H28: 管理費撥款
A29: 109.08.04 | B29: 2020-08-04 | C29: 2020-08 | D29: 1605 | F29: 360090 | G29: 存款息 | H29: 存款利息
... A33: 109.10.05 | B33: 2020-10-05 | C33: 2020-10 | D33: 1553 | F33: 463248 | G33: 存款息 | H33: 存款利息
A34: 109.10.06 | B34: 2020-10-06 | C34: 2020-10 | E34: 242550 | F34: 220698 | G34: 更換主鋼索1 | H34: 主鋼索更換
A35: 109.10.06 | B35: 2020-10-06 | C35: 2020-10 | D35: 50000 | F35: 270698 | G35: 109/10管理費撥款電梯專戶 | H35: 管理費撥款
A36: 109.11.04 | B36: 2020-11-04 | C36: 2020-11 | D36: 1605 | F36: 272303 | G36: 存款息 | H36: 存款利息
A37: 109.11.04 | B37: 2020-11-04 | C37: 2020-11 | D37: 50000 | F37: 322303 | G37: 109/11管理費撥款電梯專戶 | H37: 管理費撥款
A38: 109.12.04 | B38: 2020-12-04 | C38: 2020-12 | D38: 1553 | F38: 323856 | G38: 存款息 | H38: 存款利息
A39: 109.12.04 | B39: 2020-12-04 | C39: 2020-12 | D39: 50000 | F39: 373856 | G39: 109/12管理費撥款電梯專戶 | H39: 管理費撥款
A40: 109.12.21 | B40: 2020-12-21 | C40: 2020-12 | D40: 18 | F40: 373874 | G40: 存款息 | H40: 存款利息
A41: 110.01.04 | B41: 2021-01-04 | C41: 2021-01 | D41: 1605 | F41: 375479 | G41: 存款息 | H41: 存款利息
A42: 110.01.04 | B42: 2021-01-04 | C42: 2021-01 | D42: 50000 | F42: 425479 | G42: 110/01管理費撥款電梯專戶 | H42: 管理費撥款
A43: 110.02.01 | B43: 2021-02-01 | C43: 2021-02 | D43: 50000 | F43: 475479 | G43: 110/02管理費撥款電梯專戶 | H43: 管理費撥款
A44: 110.02.04 | B44: 2021-02-04 | C44: 2021-02 | D44: 1605 | F44: 477084 | G44: 存款息 | H44: 存款利息
A45: 110.03.04 | B45: 2021-03-04 | C45: 2021-03 | D45: 1091 | F45: 478175 | G45: 存款息 | H45: 存款利息
...

Sheet 電梯專戶月度
A1: 月份 | B1: 收入分析 | E1: 支出分析 | H1: 餘額對照
A2: 月份 | B2: 撥款 (50K/100K) | C2: 利息 | D2: 解定存 | E2: 主鋼索 | F2: 轉定存 | G2: 其他 | H2: 活儲月末 | I2: 整理檔(元大-電梯) | J2: 差額(定存) | K2: 備註
A3: 2019-04 | B3: 50000 | G3: 1250000 | H3: 1300000
A4: 2019-05 | B4: 50000 | H4: 1350000
A5: 2019-06 | B5: 50000 | C5: 129 | H5: 1400129
A6: 2019-07 | B6: 50000 | G6: 100000 | H6: 1550129
A7: 2019-08 | B7: 50000 | H7: 1600129
A8: 2019-09 | B8: 50000 | H8: 1650129
A9: 2019-10 | B9: 50000 | H9: 1700129
A10: 2019-11 | B10: 50000 | H10: 1750129
A11: 2019-12 | B11: 50000 | C11: 410 | H11: 1800539
A12: 2020-01 | B12: 100000 | H12: 1900539
A13: 2020-02 | F13: 1800000 | H13: 100539 | K13: ⚠️ 轉定存
A14: 2020-03 | B14: 50000 | C14: 1502 | H14: 152041
A15: 2020-04 | B15: 50000 | C15: 1605 | H15: 203646
A16: 2020-05 | B16: 50000 | C16: 1553 | H16: 255199
A17: 2020-06 | B17: 50000 | C17: 1733 | H17: 306932
A18: 2020-07 | B18: 50000 | C18: 1553 | H18: 358485
A19: 2020-08 | B19: 50000 | C19: 1605 | H19: 410090
A20: 2020-09 | B20: 50000 | C20: 1605 | H20: 461695
A21: 2020-10 | B21: 50000 | C21: 1553 | E21: 242550 | H21: 270698 | K21: 🔴 主鋼索更換
A22: 2020-11 | B22: 50000 | C22: 1605 | H22: 322303
A23: 2020-12 | B23: 50000 | C23: 1571 | H23: 373874
A24: 2021-01 | B24: 50000 | C24: 1605 | H24: 425479 | I24: 2225479 | J24: 1800000
A25: 2021-02 | B25: 50000 | C25: 1605 | H25: 477084 | I25: 2277084 | J25: 1800000
A26: 2021-03 | B26: 50000 | C26: 1091 | H26: 528175 | I26: 2328175 | J26: 1800000
A27: 2021-04 | B27: 50000 | C27: 1208 | H27: 579383 | I27: 2379383 | J27: 1800000
A28: 2021-05 | B28: 50000 | C28: 1169 | H28: 630552 | I28: 2430552 | J28: 1800000
A29: 2021-06 | B29: 50000 | C29: 1233 | H29: 681785 | I29: 2481785 | J29: 1800000
A30: 2021-07 | B30: 50000 | C30: 1169 | H30: 732954 | I30: 2532954 | J30: 1800000
A31: 2021-08 | B31: 50000 | C31: 1208 | H31: 784162 | I31: 2584162 | J31: 1800000
A32: 2021-09 | B32: 50000 | C32: 1208 | H32: 835370 | I32: 2635370 | J32: 1800000
A33: 2021-10 | B33: 50000 | C33: 1169 | H33: 886539 | I33: 2686539 | J33: 1800000
A34: 2021-11 | B34: 50000 | C34: 1208 | H34: 937747 | I34: 2737747 | J34: 1800000
A35: 2021-12 | B35: 50000 | C35: 1209 | H35: 988956 | I35: 2788956 | J35: 1800000
A36: 2022-01 | B36: 50000 | C36: 1208 | H36: 1040164 | I36: 2840164 | J36: 1800000
A37: 2022-02 | B37: 50000 | C37: 1208 | E37: 378000 | H37: 713372 | I37: 2513372 | J37: 1800000 | K37: 🔴 主鋼索更換
A38: 2022-03 | B38: 50000 | C38: 1091 | H38: 764463 | I38: 2564463 | J38: 1800000
A39: 2022-04 | B39: 50000 | C39: 1208 | H39: 815671 | I39: 2615671 | J39: 1800000
A40: 2022-05 | B40: 50000 | C40: 1169 | H40: 866840 | I40: 2666840 | J40: 1800000
...

Sheet 議案-游泳池
A1: 議案彙整 — 游泳池
A2: 泳池機房保養 + 設備修繕 + 周邊用品 (含分項抽出，避免高估)
A4: ─── 統計 ───
A5: 合計金額 (NT$) | B5: 698790
A6: 筆數 | B6: 44
A7: 期間 | B7: 2021-01 ~ 2025-12
A9: ─── 各年度 ───
A10: 年度 | B10: 泳池支出 (NT$)
A11: 2021 年 | B11: 74700
A12: 2022 年 | B12: 21000
A13: 2023 年 | B13: 161730
A14: 2024 年 | B14: 193460
A15: 2025 年 | B15: 247900
A17: ─── 明細 (每筆顯示原始全額 + 抽出後 pool-only 金額) ───
A18: 月份 | B18: 原始全額 (NT$) | C18: Pool-only (NT$) | D18: 工程項目 | E18: 備註
A19: 2021-01 | B19: 3000 | C19: 3000 | D19: 侑昇-泳池機房保養(109/12) | E19: 機房保養 100%
A20: 2021-02 | B20: 3000 | C20: 3000 | D20: 侑昇-泳池機房保養(110/02) | E20: 機房保養
A21: 2021-02 | B21: 3000 | C21: 3000 | D21: 侑昇-泳池機房保養(110/01) | E21: 機房保養 (1+2月補繳)
A22: 2021-03 | B22: 3000 | C22: 3000 | D22: 侑昇-泳池機房保養(110/03) | E22: 機房保養
A23: 2021-04 | B23: 3000 | C23: 3000 | D23: 侑昇-泳池機房保養(110/04) | E23: 機房保養
A24: 2021-05 | B24: 0 | C24: 0 | D24: 侑昇-泳池機房保養(110/05) | E24: 排水閥故障未保養
A25: 2021-06 | B25: 0 | C25: 0 | D25: 侑昇-泳池機房保養(110/06) | E25: 合約7月開始
A26: 2021-07 | B26: 3500 | C26: 3500 | D26: 侑昇-泳池機房保養(110/07) | E26: 機房保養 (新合約3,500/月)
A27: 2021-07 | B27: 70900 | C27: 36050 | D27: 鑫禾機電 …泳池設備修繕$36,050… | E27: 只計 泳池設備修繕 $36,050
A28: 2021-08 | B28: 3500 | C28: 3500 | D28: 侑昇-泳池機房保養(110/08) | E28: 機房保養
A29: 2021-09 | B29: 3500 | C29: 3500 | D29: 侑昇-泳池機房保養(110/09) | E29: 機房保養
A30: 2021-10 | B30: 3500 | C30: 3500 | D30: 侑昇-泳池機房保養(110/10) | E30: 機房保養
... A62: 2025-12 | B62: 4517 | C62: 4517 | D62: 購買游泳池陽傘、救生員座椅(七月) | E62: 100%
A63: 合計 | B63: 808940 | C63: 698790
A65: ─── 門票收入 vs 游泳池支出 對比 ───
A67: 年度 | B67: 門票收入 (NT$) | C67: 游泳池支出 (NT$) | D67: 赤字 (NT$) | E67: 收入抵支出 %
A68: 2021 年 | B68: 0 | C68: 74700 | D68: -74700 | E68: 0.0%
A69: 2022 年 | B69: 0 | C69: 21000 | D69: -21000 | E69: 0.0%
A70: 2023 年 | B70: 49650 | C70: 161730 | D70: -112080 | E70: 30.7%
A71: 2024 年 | B71: 52230 | C71: 193460 | D71: -141230 | E71: 27.0%
A72: 2025 年 | B72: 74060 | C72: 247900 | D72: -173840 | E72: 29.9%
A73: 合計 | B73: 175940 | C73: 698790 | D73: -522850 | E73: 25.2%
A75: 註：泳卷收入 / 泳池收入 已於 收入明細 sheet 統一改稱「門票收入」
A76: 註：游泳池支出 = 議案-游泳池 sheet 上方各年度 (機房保養 + 設備修繕 + 救生員 + 周邊用品 — pool-only)

Sheet 公共電費
A1: 月份 | B1: 公共電費 | C1: 說明
A2: 2021-01 | B2: 87413 | C2: 109年12月公共電費: 87,413
A3: 2021-02 | B3: 88215 | C3: 公共電費(109.12.11至110.01.12): 88,215
A4: 2021-03 | B4: 101777 | C4: 公共電費(110.01.13至110.2.16): 101,777
A5: 2021-04 | B5: 85178 | C5: 公共電費(110.02.17至110.03.15): 85,178
A6: 2021-05 | B6: 84824 | C6: 公共電費(110.03.17至110.04.14): 84,824
A7: 2021-06 | B7: 88643 | C7: 公共電費(110.04.16至110.05.15): 88,643
A8: 2021-07 | B8: 89266 | C8: 公共電費(110.05.17至110.06.15): 89,266
A9: 2021-08 | B9: 88231 | C9: 公共電費(110.05.17至110.06.15): 88,231
A10: 2021-09 | B10: 80066 | C10: 公共電費(110.07.13至110.08.10): 80,066
A11: 2021-10 | B11: 95341 | C11: 公共電費: 95,341
A12: 2021-11 | B12: 104138 | C12: 公共電費(110.09.10~110.12.05): 104,138
A13: 2021-12 | B13: 71935 | C13: 公共電費: 71,935
... A65: 2026-04 | B65: 92257 | C65: ◆公共電費: 92,257
A67: ─ 統計 ─
A68: 期間合計 | B68: 6431546
A69: 月均 | B69: 100492.91
A70: 中位 | B70: 97375
A71: 最高 | B71: 227933
A72: 最低 | B72: 0
A74: ─ 年度小計 ─
A75: 2021 年 | B75: 1065027
A76: 2022 年 | B76: 1183450
A77: 2023 年 | B77: 1137916
A78: 2024 年 | B78: 1510829
A79: 2025 年 | B79: 1182049
A80: 2026 年 | B80: 352275
A82: ─ 季度小計 ─
A83: 2021-Q1 | B83: 277405
A84: 2021-Q2 | B84: 258645
A85: 2021-Q3 | B85: 257563
A86: 2021-Q4 | B86: 271414
A87: 2022-Q1 | B87: 274545
A88: 2022-Q2 | B88: 265067
A89: 2022-Q3 | B89: 325650
A90: 2022-Q4 | B90: 318188
A91: 2023-Q1 | B91: 265354
A92: 2023-Q2 | B92: 262411
A93: 2023-Q3 | B93: 312400
A94: 2023-Q4 | B94: 297751
...
